{
  "timestamp": "2025-07-11T14:48:27.276322",
  "project": "ai-trackdown-pytools",
  "total_results": 1,
  "successful_suites": 0,
  "failed_suites": 1,
  "total_duration": 1.0010406970977783,
  "results": [
    {
      "type": "unit",
      "success": false,
      "duration": 1.0010406970977783,
      "output": "============================= test session starts ==============================\nplatform darwin -- Python 3.13.5, pytest-8.4.1, pluggy-1.6.0 -- /Users/masa/Projects/managed/ai-trackdown-pytools/venv/bin/python3\ncachedir: .pytest_cache\nrootdir: /Users/masa/Projects/managed/ai-trackdown-pytools\nconfigfile: pyproject.toml\nplugins: cov-6.2.1, mock-3.14.1\ncollecting ... collected 11 items / 8 errors\n\n==================================== ERRORS ====================================\n___________________ ERROR collecting tests/unit/test_cli.py ____________________\ntests/unit/test_cli.py:6: in <module>\n    from ai_trackdown_pytools.cli import app\nsrc/ai_trackdown_pytools/cli.py:12: in <module>\n    from .commands import (\nsrc/ai_trackdown_pytools/commands/__init__.py:3: in <module>\n    from ai_trackdown_pytools.commands import (\nsrc/ai_trackdown_pytools/commands/validate.py:18: in <module>\n    from ai_trackdown_pytools.utils.frontmatter import (\nsrc/ai_trackdown_pytools/utils/frontmatter.py:275: in <module>\n    class StatusWorkflowValidator:\nsrc/ai_trackdown_pytools/utils/frontmatter.py:358: in StatusWorkflowValidator\n    def get_valid_transitions(self, ticket_type: str, current_status: str) -> List[str]:\n                                                                              ^^^^\nE   NameError: name 'List' is not defined\n_______________ ERROR collecting tests/unit/test_cli_commands.py _______________\ntests/unit/test_cli_commands.py:9: in <module>\n    from ai_trackdown_pytools.cli import app\nsrc/ai_trackdown_pytools/cli.py:12: in <module>\n    from .commands import (\nsrc/ai_trackdown_pytools/commands/__init__.py:3: in <module>\n    from ai_trackdown_pytools.commands import (\nsrc/ai_trackdown_pytools/commands/validate.py:18: in <module>\n    from ai_trackdown_pytools.utils.frontmatter import (\nsrc/ai_trackdown_pytools/utils/frontmatter.py:275: in <module>\n    class StatusWorkflowValidator:\nsrc/ai_trackdown_pytools/utils/frontmatter.py:358: in StatusWorkflowValidator\n    def get_valid_transitions(self, ticket_type: str, current_status: str) -> List[str]:\n                                                                              ^^^^\nE   NameError: name 'List' is not defined\n_______________ ERROR collecting tests/unit/test_core_models.py ________________\ntests/unit/test_core_models.py:7: in <module>\n    from ai_trackdown_pytools.core.models import (\nsrc/ai_trackdown_pytools/core/models.py:99: in <module>\n    class BaseTicketModel(BaseModel):\nsrc/ai_trackdown_pytools/core/models.py:121: in BaseTicketModel\n    @validator('assignees', 'tags', 'labels')\n     ^^^^^^^^^\nE   NameError: name 'validator' is not defined\n_________________ ERROR collecting tests/unit/test_project.py __________________\nImportError while importing test module '/Users/masa/Projects/managed/ai-trackdown-pytools/tests/unit/test_project.py'.\nHint: make sure your test modules/packages have valid Python names.\nTraceback:\n/opt/homebrew/Cellar/python@3.13/3.13.5/Frameworks/Python.framework/Versions/3.13/lib/python3.13/importlib/__init__.py:88: in import_module\n    return _bootstrap._gcd_import(name[level:], package, level)\n           ^^^^^^^^^^^^^^^^^^^^^^^^^^^^^^^^^^^^^^^^^^^^^^^^^^^^\ntests/unit/test_project.py:8: in <module>\n    from ai_trackdown_pytools.core.project import Project, ProjectError\nE   ImportError: cannot import name 'ProjectError' from 'ai_trackdown_pytools.core.project' (/Users/masa/Projects/managed/ai-trackdown-pytools/src/ai_trackdown_pytools/core/project.py)\n___________________ ERROR collecting tests/unit/test_task.py ___________________\nImportError while importing test module '/Users/masa/Projects/managed/ai-trackdown-pytools/tests/unit/test_task.py'.\nHint: make sure your test modules/packages have valid Python names.\nTraceback:\n/opt/homebrew/Cellar/python@3.13/3.13.5/Frameworks/Python.framework/Versions/3.13/lib/python3.13/importlib/__init__.py:88: in import_module\n    return _bootstrap._gcd_import(name[level:], package, level)\n           ^^^^^^^^^^^^^^^^^^^^^^^^^^^^^^^^^^^^^^^^^^^^^^^^^^^^\ntests/unit/test_task.py:9: in <module>\n    from ai_trackdown_pytools.core.task import Task, TaskManager, TaskError\nE   ImportError: cannot import name 'TaskError' from 'ai_trackdown_pytools.core.task' (/Users/masa/Projects/managed/ai-trackdown-pytools/src/ai_trackdown_pytools/core/task.py)\n____________ ERROR collecting tests/unit/test_utils_frontmatter.py _____________\ntests/unit/test_utils_frontmatter.py:9: in <module>\n    from ai_trackdown_pytools.utils.frontmatter import (\nsrc/ai_trackdown_pytools/utils/frontmatter.py:275: in <module>\n    class StatusWorkflowValidator:\nsrc/ai_trackdown_pytools/utils/frontmatter.py:358: in StatusWorkflowValidator\n    def get_valid_transitions(self, ticket_type: str, current_status: str) -> List[str]:\n                                                                              ^^^^\nE   NameError: name 'List' is not defined\n________________ ERROR collecting tests/unit/test_utils_git.py _________________\nImportError while importing test module '/Users/masa/Projects/managed/ai-trackdown-pytools/tests/unit/test_utils_git.py'.\nHint: make sure your test modules/packages have valid Python names.\nTraceback:\n/opt/homebrew/Cellar/python@3.13/3.13.5/Frameworks/Python.framework/Versions/3.13/lib/python3.13/importlib/__init__.py:88: in import_module\n    return _bootstrap._gcd_import(name[level:], package, level)\n           ^^^^^^^^^^^^^^^^^^^^^^^^^^^^^^^^^^^^^^^^^^^^^^^^^^^^\ntests/unit/test_utils_git.py:8: in <module>\n    from ai_trackdown_pytools.utils.git import (\nE   ImportError: cannot import name 'GitRepo' from 'ai_trackdown_pytools.utils.git' (/Users/masa/Projects/managed/ai-trackdown-pytools/src/ai_trackdown_pytools/utils/git.py)\n_____________ ERROR collecting tests/unit/test_utils_templates.py ______________\nImportError while importing test module '/Users/masa/Projects/managed/ai-trackdown-pytools/tests/unit/test_utils_templates.py'.\nHint: make sure your test modules/packages have valid Python names.\nTraceback:\n/opt/homebrew/Cellar/python@3.13/3.13.5/Frameworks/Python.framework/Versions/3.13/lib/python3.13/importlib/__init__.py:88: in import_module\n    return _bootstrap._gcd_import(name[level:], package, level)\n           ^^^^^^^^^^^^^^^^^^^^^^^^^^^^^^^^^^^^^^^^^^^^^^^^^^^^\ntests/unit/test_utils_templates.py:8: in <module>\n    from ai_trackdown_pytools.utils.templates import (\nE   ImportError: cannot import name 'TemplateEngine' from 'ai_trackdown_pytools.utils.templates' (/Users/masa/Projects/managed/ai-trackdown-pytools/src/ai_trackdown_pytools/utils/templates.py)\n=============================== warnings summary ===============================\nvenv/lib/python3.13/site-packages/pydantic/_internal/_config.py:323\nvenv/lib/python3.13/site-packages/pydantic/_internal/_config.py:323\nvenv/lib/python3.13/site-packages/pydantic/_internal/_config.py:323\n  /Users/masa/Projects/managed/ai-trackdown-pytools/venv/lib/python3.13/site-packages/pydantic/_internal/_config.py:323: PydanticDeprecatedSince20: Support for class-based `config` is deprecated, use ConfigDict instead. Deprecated in Pydantic V2.0 to be removed in V3.0. See Pydantic V2 Migration Guide at https://errors.pydantic.dev/2.11/migration/\n    warnings.warn(DEPRECATION_MESSAGE, DeprecationWarning)\n\nvenv/lib/python3.13/site-packages/pydantic/_internal/_generate_schema.py:298\nvenv/lib/python3.13/site-packages/pydantic/_internal/_generate_schema.py:298\nvenv/lib/python3.13/site-packages/pydantic/_internal/_generate_schema.py:298\nvenv/lib/python3.13/site-packages/pydantic/_internal/_generate_schema.py:298\nvenv/lib/python3.13/site-packages/pydantic/_internal/_generate_schema.py:298\n  /Users/masa/Projects/managed/ai-trackdown-pytools/venv/lib/python3.13/site-packages/pydantic/_internal/_generate_schema.py:298: PydanticDeprecatedSince20: `json_encoders` is deprecated. See https://docs.pydantic.dev/2.11/concepts/serialization/#custom-serializers for alternatives. Deprecated in Pydantic V2.0 to be removed in V3.0. See Pydantic V2 Migration Guide at https://errors.pydantic.dev/2.11/migration/\n    warnings.warn(\n\n-- Docs: https://docs.pytest.org/en/stable/how-to/capture-warnings.html\n- generated xml file: /Users/masa/Projects/managed/ai-trackdown-pytools/test-reports/unit-tests.xml -\n=========================== short test summary info ============================\nERROR tests/unit/test_cli.py - NameError: name 'List' is not defined\nERROR tests/unit/test_cli_commands.py - NameError: name 'List' is not defined\nERROR tests/unit/test_core_models.py - NameError: name 'validator' is not def...\nERROR tests/unit/test_project.py\nERROR tests/unit/test_task.py\nERROR tests/unit/test_utils_frontmatter.py - NameError: name 'List' is not de...\nERROR tests/unit/test_utils_git.py\nERROR tests/unit/test_utils_templates.py\n!!!!!!!!!!!!!!!!!!! Interrupted: 8 errors during collection !!!!!!!!!!!!!!!!!!!!\n======================== 8 warnings, 8 errors in 0.58s =========================\n",
      "errors": "",
      "command": "/Users/masa/Projects/managed/ai-trackdown-pytools/venv/bin/python3 -m pytest /Users/masa/Projects/managed/ai-trackdown-pytools/tests/unit -v --tb=short --strict-markers --junit-xml=/Users/masa/Projects/managed/ai-trackdown-pytools/test-reports/unit-tests.xml"
    }
  ]
}